WARNING  urllib3.connectionpool:connectionpool.py:871 Retrying (Retry(total=2, connect=None, read=None, redirect=None, status=None)) after connection broken by 'NewConnectionError('<urllib3.connection.HTTPConnection object at 0x7feff1166190>: Failed to establish a new connection: [Errno 111] Connection refused')': /session/2a5fb67aa6ec8d61141542601b855b41/window/maximize
WARNING  urllib3.connectionpool:connectionpool.py:871 Retrying (Retry(total=1, connect=None, read=None, redirect=None, status=None)) after connection broken by 'NewConnectionError('<urllib3.connection.HTTPConnection object at 0x7feff11675d0>: Failed to establish a new connection: [Errno 111] Connection refused')': /session/2a5fb67aa6ec8d61141542601b855b41/window/maximize
WARNING  urllib3.connectionpool:connectionpool.py:871 Retrying (Retry(total=0, connect=None, read=None, redirect=None, status=None)) after connection broken by 'NewConnectionError('<urllib3.connection.HTTPConnection object at 0x7feff1164290>: Failed to establish a new connection: [Errno 111] Connection refused')': /session/2a5fb67aa6ec8d61141542601b855b41/window/maximize